<?xml version="1.0" ?>
<!-- =================================================================================== -->
<!-- |    This document was autogenerated by xacro from rrr_arm.xacro                  | -->
<!-- |    EDITING THIS FILE BY HAND IS NOT RECOMMENDED                                 | -->
<!-- =================================================================================== -->
<!-- Make the namespace of the robot-->
<robot name="rrr_arm">
  <!--finger radius/length-->
  <!--finger length-->
  <!--Define Rviz colors-->
  <material name="Black">
    <color rgba="0.0 0.0 0.0 1.0"/>
  </material>
  <material name="Red">
    <color rgba="0.8 0.0 0.0 1.0"/>
  </material>
  <material name="Blue">
    <color rgba="0.0 0.0 1.0 1.0"/>
  </material>
  <material name="LightBlue">
    <color rgba="0.589 0.793 1.0 1.0"/>
  </material>
  <material name="Grey">
    <color rgba="0.5 0.5 0.5 1.0"/>
  </material>
  <material name="White">
    <color rgba="1.0 1.0 1.0 1.0"/>
  </material>
  <!--=============================================================================-->
  <!--base_link-->
  <link name="base_link">
    <inertial>
      <origin rpy="0 0 0" xyz="0 0 0.075"/>
      <mass value="20"/>
      <inertia ixx="0.10416666666666667" ixy="0.0" ixz="0.0" iyy="0.10416666666666667" iyz="0.0" izz="0.13333333333333336"/>
    </inertial>
    <visual>
      <origin rpy="0.0 0.0 0.0" xyz="0.0 0.0 0.075"/>
      <geometry>
        <cylinder length="0.15" radius="0.1"/>
      </geometry>
      <material name="LightBlue"/>
    </visual>
    <collision>
      <origin rpy="0.0 0.0 0.0" xyz="0.0 0.0 0.075"/>
      <geometry>
        <cylinder length="0.15" radius="0.1"/>
      </geometry>
      &gt;
        
    </collision>
  </link>
  <joint name="joint_1" type="revolute">
    <origin rpy="0.0 0.0 0.0" xyz="0.0 0.0 0.15"/>
    <parent link="base_link"/>
    <child link="link_1"/>
    <axis xyz="0.0 0.0 1"/>
    <limit effort="300.0" lower="-2.0" upper="3.28318" velocity="1.0"/>
  </joint>
  <!--=============================================================================-->
  <!--link_1-->
  <link name="link_1">
    <inertial>
      <origin rpy="0 0 0" xyz="0 0 0.2"/>
      <mass value="5"/>
      <inertia ixx="0.07083333333333336" ixy="0.0" ixz="0.0" iyy="0.07083333333333336" iyz="0.0" izz="0.008333333333333335"/>
    </inertial>
    <visual>
      <origin rpy="0.0 0.0 0.0" xyz="0.0 0.0 0.2"/>
      <geometry>
        <cylinder length="0.4" radius="0.05"/>
      </geometry>
      <material name="Grey"/>
    </visual>
    <collision>
      <origin rpy="0.0 0.0 0.0" xyz="0.0 0.0 0.2"/>
      <geometry>
        <cylinder length="0.4" radius="0.05"/>
      </geometry>
      &gt;
        
    </collision>
  </link>
  <!-- <xacro:gazebo_grey_link_color_block link_name="link_1"> -->
  <link name="link_1_endlink">
    <inertial>
      <origin rpy="0 0 0" xyz="0 0 0.085"/>
      <mass value="1.6666666666666667"/>
      <inertia ixx="0.005402777777777779" ixy="0.0" ixz="0.0" iyy="0.005402777777777779" iyz="0.0" izz="0.0027777777777777783"/>
    </inertial>
    <visual>
      <origin rpy="0.0 0.0 0.0" xyz="0.0 0.0 0.085"/>
      <geometry>
        <cylinder length="0.17" radius="0.05500000000000001"/>
      </geometry>
      <material name="LightBlue"/>
    </visual>
    <collision>
      <origin rpy="0.0 0.0 0.0" xyz="0.0 0.0 0.085"/>
      <geometry>
        <cylinder length="0.17" radius="0.05500000000000001"/>
      </geometry>
    </collision>
  </link>
  <joint name="link_1_endjoint" type="fixed">
    <origin rpy="0.0 1.570795 0.0" xyz="-0.05 0.0 0.39"/>
    <parent link="link_1"/>
    <child link="link_1_endlink"/>
  </joint>
  <joint name="joint_2" type="revolute">
    <origin rpy="0.0 0.0 0.0" xyz="0.085 0.0 0.4"/>
    <parent link="link_1"/>
    <child link="link_2"/>
    <axis xyz="1.0 0.0 0.0"/>
    <limit effort="300.0" lower="-2.0" upper="3.28318" velocity="1.0"/>
  </joint>
  <!--=============================================================================-->
  <!--link_2-->
  <link name="link_2">
    <inertial>
      <origin rpy="0 0 0" xyz="0 0 0.25"/>
      <mass value="3"/>
      <inertia ixx="0.063725" ixy="0.0" ixz="0.0" iyy="0.063725" iyz="0.0" izz="0.0024500000000000004"/>
    </inertial>
    <visual>
      <origin rpy="0.0 0.0 0.0" xyz="0.0 0.0 0.25"/>
      <geometry>
        <cylinder length="0.5" radius="0.035"/>
      </geometry>
      <material name="Grey"/>
    </visual>
    <collision>
      <origin rpy="0.0 0.0 0.0" xyz="0.0 0.0 0.25"/>
      <geometry>
        <cylinder length="0.5" radius="0.035"/>
      </geometry>
      &gt;
        
    </collision>
  </link>
  <link name="link_2_endlink">
    <inertial>
      <origin rpy="0 0 0" xyz="0 0 0.060000000000000005"/>
      <mass value="1.0"/>
      <inertia ixx="0.0016083333333333336" ixy="0.0" ixz="0.0" iyy="0.0016083333333333336" iyz="0.0" izz="0.0008166666666666667"/>
    </inertial>
    <visual>
      <origin rpy="0.0 0.0 0.0" xyz="0.0 0.0 0.060000000000000005"/>
      <geometry>
        <cylinder length="0.12000000000000001" radius="0.038500000000000006"/>
      </geometry>
      <material name="LightBlue"/>
    </visual>
    <collision>
      <origin rpy="0.0 0.0 0.0" xyz="0.0 0.0 0.060000000000000005"/>
      <geometry>
        <cylinder length="0.12000000000000001" radius="0.038500000000000006"/>
      </geometry>
    </collision>
  </link>
  <joint name="link_2_endjoint" type="fixed">
    <origin rpy="0.0 1.570795 0.0" xyz="-0.035 0.0 0.49"/>
    <parent link="link_2"/>
    <child link="link_2_endlink"/>
  </joint>
  <joint name="joint_3" type="revolute">
    <origin rpy="0.0 0.0 0.0" xyz="0.060000000000000005 0.0 0.46499999999999997"/>
    <parent link="link_2"/>
    <child link="link_3"/>
    <axis xyz="1.0 0.0 0.0"/>
    <limit effort="300.0" lower="-2.0" upper="3.28318" velocity="1.0"/>
  </joint>
  <!--=============================================================================-->
  <!--link_3-->
  <link name="link_3">
    <inertial>
      <origin rpy="0 0 0" xyz="0 0 0.15"/>
      <mass value="3"/>
      <inertia ixx="0.023125" ixy="0.0" ixz="0.0" iyy="0.023125" iyz="0.0" izz="0.0012500000000000002"/>
    </inertial>
    <visual>
      <origin rpy="0.0 0.0 0.0" xyz="0.0 0.0 0.15"/>
      <geometry>
        <cylinder length="0.3" radius="0.025"/>
      </geometry>
      <material name="Grey"/>
    </visual>
    <collision>
      <origin rpy="0.0 0.0 0.0" xyz="0.0 0.0 0.15"/>
      <geometry>
        <cylinder length="0.3" radius="0.025"/>
      </geometry>
      &gt;
        
    </collision>
  </link>
  <joint name="joint_4" type="revolute">
    <origin rpy="0.0 0.0 0.0" xyz="0.0 0.0 0.3"/>
    <parent link="link_3"/>
    <child link="link_4"/>
    <axis xyz="0.0 0.0 01.0"/>
    <limit effort="300.0" lower="-2.0" upper="3.28318" velocity="1.0"/>
  </joint>
  <!--=============================================================================-->
  <!--link_4-->
  <link name="link_4">
    <inertial>
      <origin rpy="0 0 0" xyz="0 0 0.075"/>
      <mass value="1"/>
      <inertia ixx="0.0020833333333333333" ixy="0.0" ixz="0.0" iyy="0.0020833333333333333" iyz="0.0" izz="0.00041666666666666675"/>
    </inertial>
    <visual>
      <origin rpy="0.0 1.570795 0.0" xyz="0.0 0.0 0.0125"/>
      <geometry>
        <box size="0.05 0.05 0.15"/>
      </geometry>
      <material name="Grey"/>
    </visual>
    <collision>
      <origin rpy="0.0 0.0 0.0" xyz="0.0 0.0 0.0125"/>
      <geometry>
        <box size="0.05 0.05 0.15"/>
      </geometry>
      &gt;
        
    </collision>
  </link>
  <joint name="gripper_joint_1" type="prismatic">
    <origin rpy="0.0 0.0 0.0" xyz="0.0 0.0 0.060000000000000005"/>
    <parent link="link_4"/>
    <child link="gripper_link_1"/>
    <axis xyz="1.0 0.0 0.0"/>
    <limit effort="100.0" lower="0.01" upper="0.05" velocity="1.0"/>
  </joint>
  <joint name="gripper_joint_2" type="prismatic">
    <origin rpy="0.0 0.0 0.0" xyz="0.0 0.0 0.060000000000000005"/>
    <parent link="link_4"/>
    <child link="gripper_link_2"/>
    <axis xyz="1.0 0.0 0.0"/>
    <limit effort="100.0" lower="-0.05" upper="-0.01" velocity="1.0"/>
  </joint>
  <joint name="gripper_frame_joint" type="fixed">
    <origin rpy="0.0 0.0 0.0" xyz="0.0 0.0 0.095"/>
    <parent link="link_4"/>
    <child link="gripper_frame_cp"/>
  </joint>
  <!--=============================================================================-->
  <!--gripper_link_1-->
  <link name="gripper_link_1">
    <inertial>
      <origin rpy="0 0 0" xyz="0 0 0.035"/>
      <mass value="0.2"/>
      <inertia ixx="0.00010833333333333334" ixy="0.0" ixz="0.0" iyy="0.00010833333333333334" iyz="0.0" izz="5.333333333333333e-05"/>
    </inertial>
    <visual>
      <origin rpy="0.0 0.0 0.0" xyz="0.0 0.0 0.01"/>
      <geometry>
        <box size="0.02 0.04 0.07"/>
      </geometry>
      <material name="Grey"/>
    </visual>
    <collision>
      <origin rpy="0.0 0.0 0.0" xyz="0.0 0.0 0.01"/>
      <geometry>
        <box size="0.04 0.04 0.07"/>
      </geometry>
      &gt;
        
    </collision>
  </link>
  <!--=============================================================================-->
  <!--gripper_link_2-->
  <link name="gripper_link_2">
    <inertial>
      <origin rpy="0 0 0" xyz="0 0 0.035"/>
      <mass value="0.2"/>
      <inertia ixx="0.00010833333333333334" ixy="0.0" ixz="0.0" iyy="0.00010833333333333334" iyz="0.0" izz="5.333333333333333e-05"/>
    </inertial>
    <visual>
      <origin rpy="0.0 0.0 0.0" xyz="0.0 0.0 0.01"/>
      <geometry>
        <box size="0.02 0.04 0.07"/>
      </geometry>
      <material name="Grey"/>
    </visual>
    <collision>
      <origin rpy="0.0 0.0 0.0" xyz="0.0 0.0 0.01"/>
      <geometry>
        <box size="0.04 0.04 0.07"/>
      </geometry>
      &gt;
        
    </collision>
  </link>
  <!--=============================================================================-->
  <!--gripper_frame_cp-->
  <link name="gripper_frame_cp">
    <inertial>
      <origin rpy="0 0 0" xyz="0 0 0.0005"/>
      <mass value="0.001"/>
      <inertia ixx="4.166666666666666e-10" ixy="0.0" ixz="0.0" iyy="4.166666666666666e-10" iyz="0.0" izz="6.666666666666666e-10"/>
    </inertial>
    <visual>
      <origin rpy="0.0 0.0 0.0" xyz="0.0 0.0 0.0"/>
      <geometry>
        <box size="0.001 0.001 0.001"/>
      </geometry>
      <material name="Grey"/>
    </visual>
    <collision>
      <origin rpy="0.0 0.0 0.0" xyz="0.0 0.0 0.0"/>
      <geometry>
        <box size="0.001 0.001 0.001"/>
      </geometry>
    </collision>
  </link>
</robot>

